Workbook

Sheet DMC_NAVIGATION
A1: 🌐 DMC ERP MASTER WORKBOOK — NAVIGATION HUB
A2: Click any module below to navigate directly. All sheets have a 'Back to Home' button for quick return.
A4: 📋 SETUP & MASTER DATA
A5: Module | B5: Sheet Name | C5: Description | D5: Records | E5: Status
A6: ▶ | B6: TB_COA | C6: Chart of Accounts (Production) | D6: 45 accounts, Hierarchical, Production Ready | E6: ✅ Active | F6: Go →
A7: ▶ | B7: TB_CBE_Rates | C7: CBE Exchange Rates | D7: Daily FX rates, Source tracking | E7: ✅ Active | F7: Go →
A8: ▶ | B8: TB_Clients_Master | C8: Clients Master | D8: 10 clients, Credit limits, VAT reg | E8: ✅ Active | F8: Go →
A9: ▶ | B9: TB_Hotels_Master | C9: Hotels Master | D9: 10 hotels, Commission %, Contract rates | E9: ✅ Active | F9: Go →
A10: ▶ | B10: TB_Reps_Master | C10: Reps Master | D10: 8 reps, Float limits, Commission defaults | E10: ✅ Active | F10: Go →
A11: ▶ | B11: TB_Suppliers_Master | C11: Suppliers Master | D11: 10 suppliers, Payment terms, VAT | E11: ✅ Active | F11: Go →
A12: ▶ | B12: TB_Dimensions | C12: Analytical Dimensions | D12: 3 dimensions, 18 values, Mandatory tagging | E12: ✅ Active | F12: Go →
A14: 🔄 OPERATIONS
A15: Module | B15: Sheet Name | C15: Description | D15: Records | E15: Status
A16: ▶ | B16: TB_Master_Bookings | C16: Master Bookings | D16: 11 bookings, Auto nights, FX conversion | E16: ✅ Active | F16: Go →
A17: ▶ | B17: TB_Hotel_Accruals | C17: Hotel Accruals | D17: 10 accruals, CBE rate lookup | E17: ✅ Active | F17: Go →
A18: ▶ | B18: TB_Excursions_Sales | C18: Excursion Sales | D18: 18 tickets, Auto commission, Deposit | E18: ✅ Active | F18: Go →
A19: ▶ | B19: TB_Cash_Rep_Reconciliation | C19: Cash Reconciliation | D19: 7 daily recs, Variance analysis | E19: ✅ Active | F19: Go →
A20: ▶ | B20: TB_AP_Invoices | C20: AP Invoices | D20: 8 invoices, Due dates, VAT calc | E20: ✅ Active | F20: Go →
A21: ▶ | B21: TB_Bank_Reconciliation | C21: Bank Reconciliation | D21: 5 recs, Auto-flag unmatched | E21: ✅ Active | F21: Go →
A23: 📊 ACCOUNTING & COMPLIANCE
A24: Module | B24: Sheet Name | C24: Description | D24: Records | E24: Status
A25: ▶ | B25: TB_General_Journal | C25: General Journal | D25: 20 lines, Double-entry, FX per line | E25: ✅ Active | F25: Go →
A26: ▶ | B26: TB_Trial_Balance | C26: Trial Balance | D26: 16 accounts, Auto-calculated | E26: ✅ Active | F26: Go →
A27: ▶ | B27: TB_ETA_Integration | C27: ETA E-Invoice | D27: 10 e-invoices, Portal reconciliation | E27: ✅ Active | F27: Go →
A28: ▶ | B28: TB_Audit_Trail | C28: Audit Trail | D28: 12 entries, User ID, Timestamp | E28: ✅ Active | F28: Go →
A30: 💰 REPORTING & ANALYTICS
A31: Module | B31: Sheet Name | C31: Description | D31: Records | E31: Status
A32: ▶ | B32: TB_Budget_vs_Actual | C32: Budget vs Actual | D32: 10 accounts, Variance %, YTD | E32: ✅ Active | F32: Go →
A33: ▶ | B33: TB_Golden_Report | C33: Golden Report (TO P&L) | D33: 10 TOs, Net margin %, Action flags — CEO DASHBOARD | E33: ✅ Active | F33: Go →
A35: 🛠️ MIGRATION & ADMIN
A36: Module | B36: Sheet Name | C36: Description | D36: Records | E36: Status
A37: ▶ | B37: TB_Migration_Plan | C37: COA Migration Plan | D37: 5 phases, 28 steps — Follow strictly | E37: ✅ Active | F37: Go →
A39: 📖 DOCUMENTATION
A40: Module | B40: Sheet Name | C40: Description | D40: Records | E40: Status
A41: ▶ | B41: INDEX_User_Guide | C41: User Guide & Roadmap | D41: Complete index, Limitations, Scale-up plan | E41: ✅ Active | F41: Go →
A43: 🆕 ADDITIONAL MODULES
A44: Module | B44: Sheet Name | C44: Description | D44: Records | E44: Status
A45: ▶ | B45: TB_WHT_Quarterly | C45: Per-invoice WHT tracking for EAS quarterly filing | D45: Live / Dynamic | E45: ✅ Active | F45: Go →
A46: ▶ | B46: TB_Income_Statement | C46: Live P&L by account class, sourced from Trial Balance | D46: Live / Dynamic | E46: ✅ Active | F46: Go →
A47: ▶ | B47: TB_Balance_Sheet | C47: Live Assets = Liabilities + Equity check | D47: Live / Dynamic | E47: ✅ Active | F47: Go →

Sheet INDEX_User_Guide
A1: DMC ERP MASTER WORKBOOK - UNIFIED EDITION | H1: 🏠 Back to Home
A2: Designed for DMC Operations in Egypt | EAS & Tax Compliant | Multi-Currency | Scalable Framework
A4: MODULE INDEX
A5: Sheet Name | B5: Type | C5: Purpose | D5: Records | E5: Key Features
A6: TB_COA | B6: Setup | C6: Chart of Accounts | D6: 45 accounts | E6: IsActive flag, Multi-currency, Data Validation
A7: TB_CBE_Rates | B7: Setup | C7: Daily FX Rates | D7: 18 days | E7: USD/EUR/GBP, Source tracking
A8: TB_Clients_Master | B8: Master Data | C8: Client Registry | D8: 10 clients | E8: Credit limits, VAT reg, Payment terms
A9: TB_Hotels_Master | B9: Master Data | C9: Hotel Contracts | D9: 10 hotels | E9: Star rating, Commission %, Contract rates
A10: TB_Reps_Master | B10: Master Data | C10: Rep Registry | D10: 8 reps | E10: Float limits, Commission defaults, Hotels assigned
A11: TB_Master_Bookings | B11: Operations | C11: Booking Register | D11: 11 bookings | E11: Auto nights, FX conversion, Status tracking
A12: TB_Hotel_Accruals | B12: Operations | C12: Cost Provisions | D12: 10 accruals | E12: Linked to bookings, CBE rate lookup
A13: TB_Excursions_Sales | B13: Operations | C13: Excursion Tickets | D13: 18 tickets | E13: Auto commission, Payment method, Deposit status
A14: TB_Cash_Rep_Reconciliation | B14: Operations | C14: Daily Cash Rec | D14: 7 reconciliations | E14: Expected vs Actual, Variance analysis
A15: TB_AP_Invoices | B15: Operations | C15: Supplier Invoices | D15: 8 invoices | E15: Due dates, VAT calc, Status workflow
A16: TB_General_Journal | B16: Accounting | C16: Journal Entries | D16: 20 lines | E16: Double-entry, FX rate per line, VAT support
A17: TB_Trial_Balance | B17: Reporting | C17: Period Balance | D17: 16 accounts | E17: Auto-calculated from Journal
A20: QUICK START GUIDE
A21: Step | B21: Action | C21: Sheet | D21: Notes
A22: 1 | B22: Update CBE Rates daily | C22: TB_CBE_Rates | D22: Add new row with date and rates. All FX modules reference this sheet.
A23: 2 | B23: Register new clients/hotels/reps | C23: TB_Clients_Master, TB_Hotels_Master, TB_Reps_Master | D23: Use dropdown lists for Status and Type fields.
A24: 3 | B24: Record new bookings | C24: TB_Master_Bookings | D24: Nights auto-calculated. Total FX = Pax × Rate. Total EGP = Total FX × CBE Rate.
A25: 4 | B25: Create hotel accruals | C25: TB_Hotel_Accruals | D25: Link to Booking_Ref. Provision_EGP = Cost_FX × CBE_Rate.
A26: 5 | B26: Record excursion sales | C26: TB_Excursions_Sales | D26: Sale Amount = Pax × Unit Price. Commission auto-calculated.
A27: 6 | B27: Reconcile daily cash | C27: TB_Cash_Rep_Reconciliation | D27: Expected = Cash + POS - Commission. Variance = Actual - Expected.
A28: 7 | B28: Post journal entries | C28: TB_General_Journal | D28: Every transaction MUST have balanced Debit = Credit.
A29: 8 | B29: Review Trial Balance | C29: TB_Trial_Balance | D29: Verify Closing Balance and ensure TOTALS are BALANCED.
A31: FUTURE EXPANSION ROADMAP
A32: Module | B32: Description | C32: Priority | D32: Complexity
A33: TB_Suppliers_Master | B33: Transport, excursion, and other suppliers registry | C33: High | D33: Low
A34: TB_Inventory_Master | B34: Track excursion equipment, gifts, consumables | C34: Medium | D34: Medium
A35: TB_Employees_Payroll | B35: Salaries, social insurance, withholding tax | C35: High | D35: High
A36: TB_Bank_Reconciliation | B36: Match bank statements with journal entries | C36: High | D36: Medium
A37: TB_ETA_Integration | B37: E-invoice submission and reconciliation with tax portal | C37: Critical | D37: High
A38: TB_FX_Hedging | B38: Forward contracts and FX risk management | C38: Medium | D38: High
A39: TB_Budget_vs_Actual | B39: Monthly budget tracking and variance analysis | C39: Medium | D39: Medium
A40: TB_Agent_Performance | B40: Revenue, margin, and collection analysis per agent | C40: Low | D40: Low
A41: TB_Seasonal_Forecasting | B41: Occupancy and revenue projections by season | C41: Low | D41: High
A42: TB_Audit_Trail | B42: Log all changes with user ID and timestamp | C42: High | D42: Medium

Sheet TB_CBE_Rates
A1: MODULE: CBE EXCHANGE RATES | H1: 🏠 Back to Home
A2: Daily official rates from Central Bank of Egypt. Extend range as needed. Used by all FX modules.
A3: Date | B3: USD_Rate | C3: EUR_Rate | D3: GBP_Rate | E3: Source | F3: Last_Updated_By
A4: 2026-08-01 | B4: 48.85 | C4: 53.1 | D4: 61.9 | E4: CBE Official | F4: System
A5: 2026-08-02 | B5: 48.9 | C5: 53.05 | D5: 61.85 | E5: CBE Official | F5: System
A6: 2026-08-03 | B6: 48.92 | C6: 53.2 | D6: 62 | E6: CBE Official | F6: System
A7: 2026-08-04 | B7: 48.95 | C7: 53.15 | D7: 61.95 | E7: CBE Official | F7: System
A8: 2026-08-05 | B8: 49 | C8: 53.3 | D8: 62.1 | E8: CBE Official | F8: System
A9: 2026-08-06 | B9: 49.05 | C9: 53.25 | D9: 62.05 | E9: CBE Official | F9: System
A10: 2026-08-07 | B10: 49.1 | C10: 53.4 | D10: 62.2 | E10: CBE Official | F10: System
A11: 2026-08-08 | B11: 49.08 | C11: 53.35 | D11: 62.15 | E11: CBE Official | F11: System
A12: 2026-08-09 | B12: 49.12 | C12: 53.45 | D12: 62.25 | E12: CBE Official | F12: System
A13: 2026-08-10 | B13: 49.15 | C13: 53.5 | D13: 62.3 | E13: CBE Official | F13: System
A14: 2026-08-14 | B14: 49.05 | C14: 53.7 | D14: 62.4 | E14: CBE Official | F14: System
A15: 2026-08-15 | B15: 49.1 | C15: 53.8 | D15: 62.55 | E15: CBE Official | F15: System
... A49: 2026-09-15 | B49: 49.92 | C49: 55.45 | D49: 64.35 | E49: CBE Official | F49: System

Sheet TB_Suppliers_Master
A1: MODULE: SUPPLIERS MASTER DATA | Q1: 🏠 Back to Home
A2: Transport, excursion, and other suppliers registry. Linked to AP Invoices and Payments.
A3: Supplier_ID | B3: Supplier_Name | C3: Supplier_Type | D3: Category | E3: Contact_Person | F3: Contact_Email | G3: Phone | H3: Payment_Terms_Days | I3: Currency | J3: VAT_Registration | K3: WHT_Exempt | L3: Status | M3: Contract_Start | N3: Notes | O3: Linked_Hotel_ID
A4: SUP-001 | B4: Hurghada Transport Co. | C4: Transport | D4: Ground Transport | E4: Mr. Khaled Samy | F4: ops@hurghadatransport.com | G4: +20-65-123-4567 | H4: 15 | I4: EGP | J4: 123456789 | K4: =FALSE() -> FALSE | L4: Active | M4: 2026-01-01 | N4: Airport transfers & city tours | WHT_Exempt=FALSE (subject to 3% WHT)
A5: SUP-002 | B5: Red Sea Diving Center | C5: Excursion | D5: Water Sports | E5: Ms. Dalia Hassan | F5: bookings@rsdc.com | G5: +20-65-234-5678 | H5: 7 | I5: USD | J5: N/A | K5: =FALSE() -> FALSE | L5: Active | M5: 2026-01-15 | N5: Diving & snorkeling trips | WHT_Exempt=FALSE (subject to 3% WHT)
A6: SUP-003 | B6: Luxor Day Tours | C6: Excursion | D6: Cultural Tours | E6: Mr. Tarek El-Sayed | F6: info@luxordaytours.com | G6: +20-95-345-6789 | H6: 14 | I6: EGP | J6: 987654321 | K6: =FALSE() -> FALSE | L6: Active | M6: 2026-02-01 | N6: Luxor temple & valley tours | WHT_Exempt=FALSE (subject to 3% WHT)
A7: SUP-004 | B7: Cairo Shuttle Express | C7: Transport | D7: Inter-city | E7: Ms. Nour Ibrahim | F7: reservations@cairoshuttle.com | G7: +20-2-456-7890 | H7: 30 | I7: EGP | J7: 456789123 | K7: =FALSE() -> FALSE | L7: Active | M7: 2026-02-15 | N7: Cairo-Hurghada shuttle service | WHT_Exempt=FALSE (subject to 3% WHT)
A8: SUP-005 | B8: Desert Safari Adventures | C8: Excursion | D8: Adventure | E8: Mr. Omar Fathy | F8: adventures@desertsafari.com | G8: +20-65-567-8901 | H8: 7 | I8: USD | J8: N/A | K8: =FALSE() -> FALSE | L8: Active | M8: 2026-03-01 | N8: Quad bikes & camel rides | WHT_Exempt=FALSE (subject to 3% WHT)
A9: SUP-006 | B9: Nile Cruise Operators | C9: Excursion | D9: Cruise | E9: Ms. Laila Mostafa | F9: charter@nilecruise.com | G9: +20-65-678-9012 | H9: 21 | I9: EUR | J9: 789123456 | K9: =FALSE() -> FALSE | L9: Active | M9: 2026-03-15 | N9: Luxor-Aswan cruise packages | WHT_Exempt=FALSE (subject to 3% WHT)
A10: SUP-007 | B10: Sinai Tours & Travel | C10: Excursion | D10: Religious/Cultural | E10: Mr. Wael Hamdy | F10: bookings@sinaitt.com | G10: +20-69-789-0123 | H10: 14 | I10: EGP | J10: 321654987 | K10: =FALSE() -> FALSE | L10: Active | M10: 2026-04-01 | N10: St. Catherine & Moses Mountain | WHT_Exempt=FALSE (subject to 3% WHT)
A11: SUP-008 | B11: Hurghada Car Rental | C11: Transport | D11: Car Hire | E11: Mr. Sami Farouk | F11: rentals@hurghadacars.com | G11: +20-65-890-1234 | H11: 0 | I11: USD | J11: N/A | K11: =FALSE() -> FALSE | L11: Active | M11: 2026-04-15 | N11: Daily & weekly car rentals | WHT_Exempt=FALSE (subject to 3% WHT)
A12: SUP-009 | B12: Gift Shop Suppliers | C12: Retail | D12: Souvenirs | E12: Ms. Sara Khaled | F12: wholesale@gifts-egypt.com | G12: +20-65-901-2345 | H12: 30 | I12: EGP | J12: 654987321 | K12: =FALSE() -> FALSE | L12: Active | M12: 2026-05-01 | N12: Pharaonic souvenirs & gifts | WHT_Exempt=FALSE (subject to 3% WHT)
A13: SUP-010 | B13: Marina Yacht Charters | C13: Excursion | D13: Luxury | E13: Mr. Karim Fathy | F13: charter@marinayacht.com | G13: +20-65-012-3456 | H13: 14 | I13: EUR | J13: N/A | K13: =FALSE() -> FALSE | L13: Active | M13: 2026-05-15 | N13: Private yacht & fishing trips | WHT_Exempt=FALSE (subject to 3% WHT)
A14: SUP-HTL-001 | B14: Steigenberger Aldau Beach | C14: Hotel | O14: HTL-001
A15: SUP-HTL-002 | B15: Jaz Aquamarine Resort | C15: Hotel | O15: HTL-002
A16: SUP-HTL-003 | B16: Sunrise Grand Select | C16: Hotel | O16: HTL-003
A17: SUP-HTL-004 | B17: Sun & Sea Beach Resort | C17: Hotel | O17: HTL-006
A18: SUP-HTL-005 | B18: Coral Hills Resort | C18: Hotel | O18: HTL-007
A19: SUP-HTL-006 | B19: Blue Lagoon Palace | C19: Hotel | O19: HTL-008
A20: SUP-HTL-007 | B20: Desert Rose Plaza | C20: Hotel | O20: HTL-009
A21: SUP-HTL-008 | B21: Seagull Beach Resort | C21: Hotel | O21: HTL-010
A22: SUP-HTL-009 | B22: Pickalbatros Aqua Blu | C22: Hotel | O22: HTL-004
A23: SUP-HTL-010 | B23: Sunny Days El Palacio | C23: Hotel | O23: HTL-005

Sheet TB_Clients_Master
A1: MODULE: CLIENTS MASTER DATA | N1: 🏠 Back to Home
A2: Master registry for all tour operators, agents, and direct clients. Credit limits and payment terms.
A3: Client_ID | B3: Client_Name | C3: Country | D3: Client_Type | E3: Credit_Limit_FX | F3: Credit_Currency | G3: Payment_Terms_Days | H3: VAT_Registration | I3: Contact_Email | J3: Discount_Rate_Pct | K3: Created_Date | L3: Notes
A4: CLI-001 | B4: Alpine Sun Tours Group | C4: Austria | D4: Tour Operator | E4: 500000 | F4: EUR | G4: 30 | H4: ATU12345678 | I4: finance@alpinesun.at | J4: 0 | K4: 2026-01-15 | L4: DMC margin from hotel buy/sell, not client markup
A5: CLI-002 | B5: Nordic Wave DMC | C5: Sweden | D5: Tour Operator | E5: 300000 | F5: EUR | G5: 45 | H5: SE5566778899 | I5: accounts@nordicwave.se | J5: 0 | K5: 2026-01-20 | L5: DMC margin from hotel buy/sell, not client markup
A6: CLI-003 | B6: BritSun Holidays | C6: UK | D6: Tour Operator | E6: 250000 | F6: GBP | G6: 30 | H6: GB123456789 | I6: payments@britsun.co.uk | J6: 0 | K6: 2026-02-01 | L6: DMC margin from hotel buy/sell, not client markup
A7: CLI-004 | B7: Meridian Voyages | C7: Germany | D7: Tour Operator | E7: 400000 | F7: EUR | G7: 30 | H7: DE123456789 | I7: billing@meridian-voyages.de | J7: 0 | K7: 2026-02-10 | L7: DMC margin from hotel buy/sell, not client markup
A8: CLI-005 | B8: Red Sea Direct Bookings | C8: Egypt | D8: Walk-in | E8: 0 | F8: EGP | G8: 0 | H8: N/A | I8: N/A | J8: 0 | K8: 2026-03-01 | L8: DMC margin from hotel buy/sell, not client markup
A9: CLI-006 | B9: EuroSun Tours | C9: Germany | D9: Tour Operator | E9: 350000 | F9: EUR | G9: 30 | H9: DE987654321 | I9: finance@eurosun.de | J9: 0 | K9: 2026-03-15 | L9: DMC margin from hotel buy/sell, not client markup
A10: CLI-007 | B10: Nile Breeze | C10: Egypt | D10: Local Agent | E10: 50000 | F10: USD | G10: 15 | H10: N/A | I10: info@nilebreeze.com | J10: 0 | K10: 2026-04-01 | L10: DMC margin from hotel buy/sell, not client markup
A11: CLI-008 | B11: London Escape | C11: UK | D11: Tour Operator | E11: 200000 | F11: GBP | G11: 30 | H11: GB987654321 | I11: bookings@londonescape.co.uk | J11: 0 | K11: 2026-04-15 | L11: DMC margin from hotel buy/sell, not client markup
A12: CLI-009 | B12: Gulf Adventures | C12: UAE | D12: Tour Operator | E12: 450000 | F12: USD | G12: 45 | H12: AE123456789 | I12: accounts@gulfadventures.ae | J12: 0 | K12: 2026-05-01 | L12: DMC margin from hotel buy/sell, not client markup
A13: CLI-010 | B13: SunSeeker Travel | C13: France | D13: Tour Operator | E13: 200000 | F13: EUR | G13: 60 | H13: FR12345678901 | I13: compta@sunseeker.fr | J13: 0 | K13: 2026-06-01 | L13: DMC margin from hotel buy/sell, not client markup

Sheet TB_Hotels_Master
A1: MODULE: HOTELS MASTER DATA | Q1: 🏠 Back to Home
A2: Contracted hotels with rates, commissions, and payment terms. Linked to bookings and accruals.
A3: Hotel_ID | B3: Hotel_Name | C3: Star_Rating | D3: Location | E3: Contact_Person | F3: Contact_Email | G3: Currency | H3: Buying_Rate_FX | I3: Selling_Rate_FX | J3: DMC_Margin_FX | K3: DMC_Margin_Pct | L3: Payment_Terms_Days | M3: Status | N3: Contract_Start | O3: Supplier_ID
A4: HTL-001 | B4: Steigenberger Aldau Beach | C4: 5 | D4: Hurghada | E4: Mr. Ahmed Hassan | F4: ahmed@steigenberger.com | G4: EUR | H4: 72 | I4: 90 | J4: =I4-H4 -> 18 | K4: =(I4-H4)/I4 -> 0.2 | L4: 30 | M4: Active | N4: 2026-01-01 | O4: =IFERROR(INDEX(TB_Suppliers_Master!$A$4:$A$23,MATCH(A4,TB_Suppliers_Master!$O$4:$O$23,0)),"") -> SUP-HTL-001
A5: HTL-002 | B5: Jaz Aquamarine Resort | C5: 5 | D5: Hurghada | E5: Ms. Sara Khaled | F5: sara@jazhotels.com | G5: EUR | H5: 65 | I5: 82 | J5: =I5-H5 -> 17 | K5: =(I5-H5)/I5 -> 0.20731707 | L5: 30 | M5: Active | N5: 2026-01-01 | O5: =IFERROR(INDEX(TB_Suppliers_Master!$A$4:$A$23,MATCH(A5,TB_Suppliers_Master!$O$4:$O$23,0)),"") -> SUP-HTL-002
A6: HTL-003 | B6: Sunrise Grand Select | C6: 5 | D6: Hurghada | E6: Mr. Karim Fathy | F6: karim@sunrise.com | G6: EUR | H6: 62 | I6: 78 | J6: =I6-H6 -> 16 | K6: =(I6-H6)/I6 -> 0.20512821 | L6: 45 | M6: Active | N6: 2026-01-01 | O6: =IFERROR(INDEX(TB_Suppliers_Master!$A$4:$A$23,MATCH(A6,TB_Suppliers_Master!$O$4:$O$23,0)),"") -> SUP-HTL-003
A7: HTL-004 | B7: Pickalbatros Aqua Blu | C7: 4 | D7: Hurghada | E7: Ms. Dina Samir | F7: dina@pickalbatros.com | G7: EUR | H7: 48 | I7: 60 | J7: =I7-H7 -> 12 | K7: =(I7-H7)/I7 -> 0.2 | L7: 30 | M7: Active | N7: 2026-01-01 | O7: =IFERROR(INDEX(TB_Suppliers_Master!$A$4:$A$23,MATCH(A7,TB_Suppliers_Master!$O$4:$O$23,0)),"") -> SUP-HTL-009
A8: HTL-005 | B8: Sunny Days El Palacio | C8: 4 | D8: Hurghada | E8: Mr. Hossam Ali | F8: hossam@sunnydays.com | G8: EUR | H8: 42 | I8: 53 | J8: =I8-H8 -> 11 | K8: =(I8-H8)/I8 -> 0.20754717 | L8: 30 | M8: Active | N8: 2026-01-01 | O8: =IFERROR(INDEX(TB_Suppliers_Master!$A$4:$A$23,MATCH(A8,TB_Suppliers_Master!$O$4:$O$23,0)),"") -> SUP-HTL-010
A9: HTL-006 | B9: Sun & Sea Beach Resort | C9: 5 | D9: Hurghada | E9: Mr. Tarek Salah | F9: tarek@sunsea.com | G9: EUR | H9: 76 | I9: 95 | J9: =I9-H9 -> 19 | K9: =(I9-H9)/I9 -> 0.2 | L9: 30 | M9: Active | N9: 2026-02-01 | O9: =IFERROR(INDEX(TB_Suppliers_Master!$A$4:$A$23,MATCH(A9,TB_Suppliers_Master!$O$4:$O$23,0)),"") -> SUP-HTL-004
A10: HTL-007 | B10: Coral Hills Resort | C10: 4 | D10: Hurghada | E10: Ms. Nour Ibrahim | F10: nour@coralhills.com | G10: USD | H10: 60 | I10: 75 | J10: =I10-H10 -> 15 | K10: =(I10-H10)/I10 -> 0.2 | L10: 30 | M10: Active | N10: 2026-02-01 | O10: =IFERROR(INDEX(TB_Suppliers_Master!$A$4:$A$23,MATCH(A10,TB_Suppliers_Master!$O$4:$O$23,0)),"") -> SUP-HTL-005
A11: HTL-008 | B11: Blue Lagoon Palace | C11: 5 | D11: Hurghada | E11: Mr. Sami Farouk | F11: sami@bluelagoon.com | G11: GBP | H11: 68 | I11: 85 | J11: =I11-H11 -> 17 | K11: =(I11-H11)/I11 -> 0.2 | L11: 45 | M11: Active | N11: 2026-03-01 | O11: =IFERROR(INDEX(TB_Suppliers_Master!$A$4:$A$23,MATCH(A11,TB_Suppliers_Master!$O$4:$O$23,0)),"") -> SUP-HTL-006
A12: HTL-009 | B12: Desert Rose Plaza | C12: 4 | D12: Hurghada | E12: Ms. Laila Mostafa | F12: laila@desertrose.com | G12: USD | H12: 56 | I12: 70 | J12: =I12-H12 -> 14 | K12: =(I12-H12)/I12 -> 0.2 | L12: 30 | M12: Active | N12: 2026-03-01 | O12: =IFERROR(INDEX(TB_Suppliers_Master!$A$4:$A$23,MATCH(A12,TB_Suppliers_Master!$O$4:$O$23,0)),"") -> SUP-HTL-007
A13: HTL-010 | B13: Seagull Beach Resort | C13: 4 | D13: Hurghada | E13: Mr. Wael Hamdy | F13: wael@seagull.com | G13: EUR | H13: 52 | I13: 65 | J13: =I13-H13 -> 13 | K13: =(I13-H13)/I13 -> 0.2 | L13: 30 | M13: Active | N13: 2026-04-01 | O13: =IFERROR(INDEX(TB_Suppliers_Master!$A$4:$A$23,MATCH(A13,TB_Suppliers_Master!$O$4:$O$23,0)),"") -> SUP-HTL-008

Sheet TB_Reps_Master
A1: MODULE: REPS MASTER DATA | N1: 🏠 Back to Home
A2: Resort representatives with assigned hotels, commission rates, and cash float limits.
A3: Rep_ID | B3: Rep_Name | C3: Nationality | D3: Hotel_Assigned | E3: Base_Salary_EGP | F3: Commission_Rate_Default | G3: Cash_Float_EGP | H3: Start_Date | I3: Status | J3: Emergency_Contact | L3: Client_ID (linked)
A4: REP-01 | B4: Mohamed Ali | C4: Egyptian | D4: Steigenberger Aldau Beach | E4: 5000 | F4: 0.1 | G4: 2000 | H4: 2026-01-15 | I4: Active | J4: +20-100-111-2222 | L4: =IFERROR(INDEX(TB_Master_Bookings!$B$4:$B$1000,MATCH(INDEX(TB_Hotels_Master!$A$4:$A$1000,MATCH(D4,TB_Hotels_Master!$B$4:$B$1000,0)),TB_Master_Bookings!$O$4:$O$1000,0)),"") -> CLI-001
A5: REP-02 | B5: Ahmed Ibrahim | C5: Egyptian | D5: Jaz Aquamarine Resort | E5: 5000 | F5: 0.1 | G5: 2000 | H5: 2026-02-01 | I5: Active | J5: +20-100-333-4444 | L5: =IFERROR(INDEX(TB_Master_Bookings!$B$4:$B$1000,MATCH(INDEX(TB_Hotels_Master!$A$4:$A$1000,MATCH(D5,TB_Hotels_Master!$B$4:$B$1000,0)),TB_Master_Bookings!$O$4:$O$1000,0)),"") -> CLI-002
A6: REP-03 | B6: Sara Hassan | C6: Egyptian | D6: Sunrise Grand Select | E6: 5000 | F6: 0.1 | G6: 2000 | H6: 2026-01-20 | I6: Active | J6: +20-100-555-6666 | L6: =IFERROR(INDEX(TB_Master_Bookings!$B$4:$B$1000,MATCH(INDEX(TB_Hotels_Master!$A$4:$A$1000,MATCH(D6,TB_Hotels_Master!$B$4:$B$1000,0)),TB_Master_Bookings!$O$4:$O$1000,0)),"") -> CLI-003
A7: REP-04 | B7: Khaled Omar | C7: Egyptian | D7: Pickalbatros Aqua Blu | E7: 5000 | F7: 0.1 | G7: 2000 | H7: 2026-03-01 | I7: Active | J7: +20-100-777-8888 | L7: =IFERROR(INDEX(TB_Master_Bookings!$B$4:$B$1000,MATCH(INDEX(TB_Hotels_Master!$A$4:$A$1000,MATCH(D7,TB_Hotels_Master!$B$4:$B$1000,0)),TB_Master_Bookings!$O$4:$O$1000,0)),"") -> CLI-004
A8: REP-05 | B8: Lina Farouk | C8: Egyptian | D8: Sunny Days El Palacio | E8: 5000 | F8: 0.1 | G8: 2000 | H8: 2026-04-01 | I8: On Leave | J8: +20-100-999-0000 | L8: =IFERROR(INDEX(TB_Master_Bookings!$B$4:$B$1000,MATCH(INDEX(TB_Hotels_Master!$A$4:$A$1000,MATCH(D8,TB_Hotels_Master!$B$4:$B$1000,0)),TB_Master_Bookings!$O$4:$O$1000,0)),"") -> CLI-005
A9: REP-HRG-01 | B9: Omar Fathy | C9: Egyptian | D9: Sun & Sea Beach Resort | E9: 5500 | F9: 0.1 | G9: 2500 | H9: 2026-05-01 | I9: Active | J9: +20-101-111-2222 | L9: =IFERROR(INDEX(TB_Master_Bookings!$B$4:$B$1000,MATCH(INDEX(TB_Hotels_Master!$A$4:$A$1000,MATCH(D9,TB_Hotels_Master!$B$4:$B$1000,0)),TB_Master_Bookings!$O$4:$O$1000,0)),"") -> CLI-006
A10: REP-HRG-02 | B10: Nadia Samir | C10: Egyptian | D10: Blue Lagoon Palace | E10: 5500 | F10: 0.1 | G10: 2500 | H10: 2026-05-15 | I10: Active | J10: +20-101-333-4444 | L10: =IFERROR(INDEX(TB_Master_Bookings!$B$4:$B$1000,MATCH(INDEX(TB_Hotels_Master!$A$4:$A$1000,MATCH(D10,TB_Hotels_Master!$B$4:$B$1000,0)),TB_Master_Bookings!$O$4:$O$1000,0)),"") -> CLI-008
A11: REP-HRG-03 | B11: Tamer Hosny | C11: Egyptian | D11: Coral Hills Resort | E11: 5500 | F11: 0.1 | G11: 2500 | H11: 2026-06-01 | I11: Active | J11: +20-101-555-6666 | L11: =IFERROR(INDEX(TB_Master_Bookings!$B$4:$B$1000,MATCH(INDEX(TB_Hotels_Master!$A$4:$A$1000,MATCH(D11,TB_Hotels_Master!$B$4:$B$1000,0)),TB_Master_Bookings!$O$4:$O$1000,0)),"") -> CLI-007

Sheet TB_Master_Bookings
A1: MODULE: MASTER BOOKINGS | R1: 🏠 Back to Home
A2: All inbound bookings from tour operators and direct clients. Auto-calculates nights, total FX, and EGP.
A3: Booking_Ref | B3: Client_ID | C3: Client_Name | D3: Agent_Name | E3: Pax_Count | F3: Check_In | G3: Check_Out | H3: Nights | I3: Currency | J3: Contracted_Rate_Foreign | K3: Total_FX | L3: CBE_Rate_at_Departure | M3: Total_EGP | N3: Status | O3: Hotel_ID | P3: Hotel_Provision_EGP
A4: HRG-2026-0815 | B4: CLI-001 | C4: =IF(B4="","",IFERROR(INDEX(TB_Clients_Master!$B$4:$B$1000,MATCH(B4,TB_Clients_Master!$A$4:$A$1000,0)),"INVALID CLIENT ID")) -> Alpine Sun Tours Group | D4: Alpine Sun Tours (Austria) | E4: 200 | F4: 2026-08-01 | G4: 2026-08-08 | H4: =G4-F4 -> 7 | I4: EUR | J4: 90 | K4: =IF(OR(E4="",H4="",J4=""),"",E4*H4*J4) -> 126000 | L4: 53.35 | M4: =K4*L4 -> 6722100 | N4: Checked Out | O4: HTL-001 | P4: =IFERROR(INDEX(TB_Hotel_Accruals!$I$4:$I$1000,MATCH(A4,TB_Hotel_Accruals!$B$4:$B$1000,0)),0) -> 5377680
A5: HRG-2026-0816 | B5: CLI-002 | C5: =IF(B5="","",IFERROR(INDEX(TB_Clients_Master!$B$4:$B$1000,MATCH(B5,TB_Clients_Master!$A$4:$A$1000,0)),"INVALID CLIENT ID")) -> Nordic Wave DMC | D5: Nordic Wave DMC (Sweden) | E5: 45 | F5: 2026-08-02 | G5: 2026-08-09 | H5: =G5-F5 -> 7 | I5: USD | J5: 82 | K5: =IF(OR(E5="",H5="",J5=""),"",E5*H5*J5) -> 25830 | L5: 49.12 | M5: =K5*L5 -> 1268769.6 | N5: Checked Out | O5: HTL-002 | P5: =IFERROR(INDEX(TB_Hotel_Accruals!$I$4:$I$1000,MATCH(A5,TB_Hotel_Accruals!$B$4:$B$1000,0)),0) -> 1005732
A6: HRG-2026-0817 | B6: CLI-003 | C6: =IF(B6="","",IFERROR(INDEX(TB_Clients_Master!$B$4:$B$1000,MATCH(B6,TB_Clients_Master!$A$4:$A$1000,0)),"INVALID CLIENT ID")) -> BritSun Holidays | D6: BritSun Holidays (UK) | E6: 30 | F6: 2026-08-03 | G6: 2026-08-10 | H6: =G6-F6 -> 7 | I6: GBP | J6: 78 | K6: =IF(OR(E6="",H6="",J6=""),"",E6*H6*J6) -> 16380 | L6: 62.3 | M6: =K6*L6 -> 1020474 | N6: Checked Out | O6: HTL-003 | P6: =IFERROR(INDEX(TB_Hotel_Accruals!$I$4:$I$1000,MATCH(A6,TB_Hotel_Accruals!$B$4:$B$1000,0)),0) -> 811146
A7: HRG-2026-0818 | B7: CLI-004 | C7: =IF(B7="","",IFERROR(INDEX(TB_Clients_Master!$B$4:$B$1000,MATCH(B7,TB_Clients_Master!$A$4:$A$1000,0)),"INVALID CLIENT ID")) -> Meridian Voyages | D7: Meridian Voyages (Germany) | E7: 60 | F7: 2026-08-01 | G7: 2026-08-07 | H7: =G7-F7 -> 6 | I7: EUR | J7: 60 | K7: =IF(OR(E7="",H7="",J7=""),"",E7*H7*J7) -> 21600 | L7: 53.4 | M7: =K7*L7 -> 1153440 | N7: Checked Out | O7: HTL-004 | P7: =IFERROR(INDEX(TB_Hotel_Accruals!$I$4:$I$1000,MATCH(A7,TB_Hotel_Accruals!$B$4:$B$1000,0)),0) -> 922752
A8: HRG-2026-0819 | B8: CLI-005 | C8: =IF(B8="","",IFERROR(INDEX(TB_Clients_Master!$B$4:$B$1000,MATCH(B8,TB_Clients_Master!$A$4:$A$1000,0)),"INVALID CLIENT ID")) -> Red Sea Direct Bookings | D8: Direct / Walk-in | E8: 12 | F8: 2026-08-04 | G8: 2026-08-09 | H8: =G8-F8 -> 5 | I8: USD | J8: 53 | K8: =IF(OR(E8="",H8="",J8=""),"",E8*H8*J8) -> 3180 | L8: 49.12 | M8: =K8*L8 -> 156201.6 | N8: Checked Out | O8: HTL-005 | P8: =IFERROR(INDEX(TB_Hotel_Accruals!$I$4:$I$1000,MATCH(A8,TB_Hotel_Accruals!$B$4:$B$1000,0)),0) -> 123782.4
A9: HRG-2026-0820 | B9: CLI-010 | C9: =IF(B9="","",IFERROR(INDEX(TB_Clients_Master!$B$4:$B$1000,MATCH(B9,TB_Clients_Master!$A$4:$A$1000,0)),"INVALID CLIENT ID")) -> SunSeeker Travel | D9: SunSeeker Travel (France) | E9: 80 | F9: 2026-08-15 | G9: 2026-08-22 | H9: =G9-F9 -> 7 | I9: EUR | J9: 95 | K9: =IF(OR(E9="",H9="",J9=""),"",E9*H9*J9) -> 53200 | L9: 53.5 | M9: =K9*L9 -> 2846200 | N9: Confirmed | P9: =IFERROR(INDEX(TB_Hotel_Accruals!$I$4:$I$1000,MATCH(A9,TB_Hotel_Accruals!$B$4:$B$1000,0)),0) -> 0
A10: MBR-2026-0001 | B10: CLI-006 | C10: =IF(B10="","",IFERROR(INDEX(TB_Clients_Master!$B$4:$B$1000,MATCH(B10,TB_Clients_Master!$A$4:$A$1000,0)),"INVALID CLIENT ID")) -> EuroSun Tours | D10: Berlin Leisure | E10: 200 | F10: 2026-08-15 | G10: 2026-08-22 | H10: =G10-F10 -> 7 | I10: EUR | J10: 95 | K10: =IF(OR(E10="",H10="",J10=""),"",E10*H10*J10) -> 133000 | L10: 54.2 | M10: =K10*L10 -> 7208600 | N10: Invoiced | O10: HTL-006 | P10: =IFERROR(INDEX(TB_Hotel_Accruals!$I$4:$I$1000,MATCH(A10,TB_Hotel_Accruals!$B$4:$B$1000,0)),0) -> 5766880
A11: MBR-2026-0002 | B11: CLI-007 | C11: =IF(B11="","",IFERROR(INDEX(TB_Clients_Master!$B$4:$B$1000,MATCH(B11,TB_Clients_Master!$A$4:$A$1000,0)),"INVALID CLIENT ID")) -> Nile Breeze | D11: Cairo Gateway | E11: 46 | F11: 2026-08-15 | G11: 2026-08-22 | H11: =G11-F11 -> 7 | I11: USD | J11: 75 | K11: =IF(OR(E11="",H11="",J11=""),"",E11*H11*J11) -> 24150 | L11: 49.3 | M11: =K11*L11 -> 1190595 | N11: Invoiced | O11: HTL-007 | P11: =IFERROR(INDEX(TB_Hotel_Accruals!$I$4:$I$1000,MATCH(A11,TB_Hotel_Accruals!$B$4:$B$1000,0)),0) -> 952476
A12: MBR-2026-0003 | B12: CLI-008 | C12: =IF(B12="","",IFERROR(INDEX(TB_Clients_Master!$B$4:$B$1000,MATCH(B12,TB_Clients_Master!$A$4:$A$1000,0)),"INVALID CLIENT ID")) -> London Escape | D12: UK Direct | E12: 32 | F12: 2026-08-16 | G12: 2026-08-24 | H12: =G12-F12 -> 8 | I12: GBP | J12: 85 | K12: =IF(OR(E12="",H12="",J12=""),"",E12*H12*J12) -> 21760 | L12: 63.25 | M12: =K12*L12 -> 1376320 | N12: Invoiced | O12: HTL-008 | P12: =IFERROR(INDEX(TB_Hotel_Accruals!$I$4:$I$1000,MATCH(A12,TB_Hotel_Accruals!$B$4:$B$1000,0)),0) -> 1101056
A13: MBR-2026-0004 | B13: CLI-009 | C13: =IF(B13="","",IFERROR(INDEX(TB_Clients_Master!$B$4:$B$1000,MATCH(B13,TB_Clients_Master!$A$4:$A$1000,0)),"INVALID CLIENT ID")) -> Gulf Adventures | D13: Gulf Reps | E13: 120 | F13: 2026-08-17 | G13: 2026-08-22 | H13: =G13-F13 -> 5 | I13: USD | J13: 70 | K13: =IF(OR(E13="",H13="",J13=""),"",E13*H13*J13) -> 42000 | L13: 49.3 | M13: =K13*L13 -> 2070600 | N13: Invoiced | O13: HTL-009 | P13: =IFERROR(INDEX(TB_Hotel_Accruals!$I$4:$I$1000,MATCH(A13,TB_Hotel_Accruals!$B$4:$B$1000,0)),0) -> 1656480
A14: MBR-2026-0005 | B14: CLI-005 | C14: =IF(B14="","",IFERROR(INDEX(TB_Clients_Master!$B$4:$B$1000,MATCH(B14,TB_Clients_Master!$A$4:$A$1000,0)),"INVALID CLIENT ID")) -> Red Sea Direct Bookings | D14: Hurghada Direct | E14: 85 | F14: 2026-08-18 | G14: 2026-08-25 | H14: =G14-F14 -> 7 | I14: EUR | J14: 65 | K14: =IF(OR(E14="",H14="",J14=""),"",E14*H14*J14) -> 38675 | L14: 54.4 | M14: =K14*L14 -> 2103920 | N14: Invoiced | O14: HTL-010 | P14: =IFERROR(INDEX(TB_Hotel_Accruals!$I$4:$I$1000,MATCH(A14,TB_Hotel_Accruals!$B$4:$B$1000,0)),0) -> 1683136
C15: =IF(B15="","",IFERROR(INDEX(TB_Clients_Master!$B$4:$B$1000,MATCH(B15,TB_Clients_Master!$A$4:$A$1000,0)),"INVALID CLIENT ID")) | K15: =IF(OR(E15="",H15="",J15=""),"",E15*H15*J15) | P15: =IFERROR(INDEX(TB_Hotel_Accruals!$I$4:$I$1000,MATCH(A15,TB_Hotel_Accruals!$B$4:$B$1000,0)),0) -> 0
C16: =IF(B16="","",IFERROR(INDEX(TB_Clients_Master!$B$4:$B$1000,MATCH(B16,TB_Clients_Master!$A$4:$A$1000,0)),"INVALID CLIENT ID")) | K16: =IF(OR(E16="",H16="",J16=""),"",E16*H16*J16) | P16: =IFERROR(INDEX(TB_Hotel_Accruals!$I$4:$I$1000,MATCH(A16,TB_Hotel_Accruals!$B$4:$B$1000,0)),0) -> 0
C17: =IF(B17="","",IFERROR(INDEX(TB_Clients_Master!$B$4:$B$1000,MATCH(B17,TB_Clients_Master!$A$4:$A$1000,0)),"INVALID CLIENT ID")) | K17: =IF(OR(E17="",H17="",J17=""),"",E17*H17*J17) | P17: =IFERROR(INDEX(TB_Hotel_Accruals!$I$4:$I$1000,MATCH(A17,TB_Hotel_Accruals!$B$4:$B$1000,0)),0) -> 0
C18: =IF(B18="","",IFERROR(INDEX(TB_Clients_Master!$B$4:$B$1000,MATCH(B18,TB_Clients_Master!$A$4:$A$1000,0)),"INVALID CLIENT ID")) | K18: =IF(OR(E18="",H18="",J18=""),"",E18*H18*J18) | P18: =IFERROR(INDEX(TB_Hotel_Accruals!$I$4:$I$1000,MATCH(A18,TB_Hotel_Accruals!$B$4:$B$1000,0)),0) -> 0
C19: =IF(B19="","",IFERROR(INDEX(TB_Clients_Master!$B$4:$B$1000,MATCH(B19,TB_Clients_Master!$A$4:$A$1000,0)),"INVALID CLIENT ID")) | K19: =IF(OR(E19="",H19="",J19=""),"",E19*H19*J19) | P19: =IFERROR(INDEX(TB_Hotel_Accruals!$I$4:$I$1000,MATCH(A19,TB_Hotel_Accruals!$B$4:$B$1000,0)),0) -> 0
K20: =IF(OR(E20="",H20="",J20=""),"",E20*H20*J20)
K21: =IF(OR(E21="",H21="",J21=""),"",E21*H21*J21)
K22: =IF(OR(E22="",H22="",J22=""),"",E22*H22*J22)
K23: =IF(OR(E23="",H23="",J23=""),"",E23*H23*J23)
K24: =IF(OR(E24="",H24="",J24=""),"",E24*H24*J24)
K25: =IF(OR(E25="",H25="",J25=""),"",E25*H25*J25)
K26: =IF(OR(E26="",H26="",J26=""),"",E26*H26*J26)
K27: =IF(OR(E27="",H27="",J27=""),"",E27*H27*J27)
K28: =IF(OR(E28="",H28="",J28=""),"",E28*H28*J28)
K29: =IF(OR(E29="",H29="",J29=""),"",E29*H29*J29)
K30: =IF(OR(E30="",H30="",J30=""),"",E30*H30*J30)
K31: =IF(OR(E31="",H31="",J31=""),"",E31*H31*J31)
... K1000: =IF(OR(E1000="",H1000="",J1000=""),"",E1000*H1000*J1000)

Sheet TB_Hotel_Accruals
A1: MODULE: HOTEL ACCRUALS | L1: 🏠 Back to Home
A2: Cost provisions for hotel stays. Linked to bookings via Booking_Ref. Auto-converts FX to EGP.
A3: Accrual_ID | B3: Booking_Ref | C3: Hotel_ID | D3: Hotel_Name | E3: Check_Out_Date | F3: Currency | G3: Cost_Foreign | H3: CBE_Rate | I3: Provision_EGP | J3: Status
A4: ACR-0001 | B4: HRG-2026-0815 | C4: =IFERROR(INDEX(TB_Master_Bookings!$O$4:$O$1000,MATCH(B4,TB_Master_Bookings!$A$4:$A$1000,0)),"") -> HTL-001 | D4: =IF(C4="","",IFERROR(INDEX(TB_Hotels_Master!$B$4:$B$1000,MATCH(C4,TB_Hotels_Master!$A$4:$A$1000,0)),"HOTEL NOT FOUND")) -> Steigenberger Aldau Beach | E4: 2026-08-08 | F4: EUR | G4: =IFERROR(INDEX(TB_Master_Bookings!$H$4:$H$1000,MATCH(B4,TB_Master_Bookings!$A$4:$A$1000,0))*INDEX(TB_Master_Bookings!$E$4:$E$1000,MATCH(B4,TB_Master_Bookings!$A$4:$A$1000,0))*INDEX(TB_Hotels_Master!$H$4:$H$1000,MATCH(C4,TB_Hotels_Master!$A$4:$A$1000,0)),0) -> 100800 | H4: =IFERROR(INDEX(TB_Master_Bookings!$L$4:$L$1000,MATCH(B4,TB_Master_Bookings!$A$4:$A$1000,0)),0) -> 53.35 | I4: =G4*H4 -> 5377680 | J4: Posted
A5: ACR-0002 | B5: HRG-2026-0816 | C5: =IFERROR(INDEX(TB_Master_Bookings!$O$4:$O$1000,MATCH(B5,TB_Master_Bookings!$A$4:$A$1000,0)),"") -> HTL-002 | D5: =IF(C5="","",IFERROR(INDEX(TB_Hotels_Master!$B$4:$B$1000,MATCH(C5,TB_Hotels_Master!$A$4:$A$1000,0)),"HOTEL NOT FOUND")) -> Jaz Aquamarine Resort | E5: 2026-08-09 | F5: EUR | G5: =IFERROR(INDEX(TB_Master_Bookings!$H$4:$H$1000,MATCH(B5,TB_Master_Bookings!$A$4:$A$1000,0))*INDEX(TB_Master_Bookings!$E$4:$E$1000,MATCH(B5,TB_Master_Bookings!$A$4:$A$1000,0))*INDEX(TB_Hotels_Master!$H$4:$H$1000,MATCH(C5,TB_Hotels_Master!$A$4:$A$1000,0)),0) -> 20475 | H5: =IFERROR(INDEX(TB_Master_Bookings!$L$4:$L$1000,MATCH(B5,TB_Master_Bookings!$A$4:$A$1000,0)),0) -> 49.12 | I5: =G5*H5 -> 1005732 | J5: Posted
A6: ACR-0003 | B6: HRG-2026-0817 | C6: =IFERROR(INDEX(TB_Master_Bookings!$O$4:$O$1000,MATCH(B6,TB_Master_Bookings!$A$4:$A$1000,0)),"") -> HTL-003 | D6: =IF(C6="","",IFERROR(INDEX(TB_Hotels_Master!$B$4:$B$1000,MATCH(C6,TB_Hotels_Master!$A$4:$A$1000,0)),"HOTEL NOT FOUND")) -> Sunrise Grand Select | E6: 2026-08-10 | F6: EUR | G6: =IFERROR(INDEX(TB_Master_Bookings!$H$4:$H$1000,MATCH(B6,TB_Master_Bookings!$A$4:$A$1000,0))*INDEX(TB_Master_Bookings!$E$4:$E$1000,MATCH(B6,TB_Master_Bookings!$A$4:$A$1000,0))*INDEX(TB_Hotels_Master!$H$4:$H$1000,MATCH(C6,TB_Hotels_Master!$A$4:$A$1000,0)),0) -> 13020 | H6: =IFERROR(INDEX(TB_Master_Bookings!$L$4:$L$1000,MATCH(B6,TB_Master_Bookings!$A$4:$A$1000,0)),0) -> 62.3 | I6: =G6*H6 -> 811146 | J6: Posted
A7: ACR-0004 | B7: HRG-2026-0818 | C7: =IFERROR(INDEX(TB_Master_Bookings!$O$4:$O$1000,MATCH(B7,TB_Master_Bookings!$A$4:$A$1000,0)),"") -> HTL-004 | D7: =IF(C7="","",IFERROR(INDEX(TB_Hotels_Master!$B$4:$B$1000,MATCH(C7,TB_Hotels_Master!$A$4:$A$1000,0)),"HOTEL NOT FOUND")) -> Pickalbatros Aqua Blu | E7: 2026-08-07 | F7: EUR | G7: =IFERROR(INDEX(TB_Master_Bookings!$H$4:$H$1000,MATCH(B7,TB_Master_Bookings!$A$4:$A$1000,0))*INDEX(TB_Master_Bookings!$E$4:$E$1000,MATCH(B7,TB_Master_Bookings!$A$4:$A$1000,0))*INDEX(TB_Hotels_Master!$H$4:$H$1000,MATCH(C7,TB_Hotels_Master!$A$4:$A$1000,0)),0) -> 17280 | H7: =IFERROR(INDEX(TB_Master_Bookings!$L$4:$L$1000,MATCH(B7,TB_Master_Bookings!$A$4:$A$1000,0)),0) -> 53.4 | I7: =G7*H7 -> 922752 | J7: Posted
A8: ACR-0005 | B8: HRG-2026-0819 | C8: =IFERROR(INDEX(TB_Master_Bookings!$O$4:$O$1000,MATCH(B8,TB_Master_Bookings!$A$4:$A$1000,0)),"") -> HTL-005 | D8: =IF(C8="","",IFERROR(INDEX(TB_Hotels_Master!$B$4:$B$1000,MATCH(C8,TB_Hotels_Master!$A$4:$A$1000,0)),"HOTEL NOT FOUND")) -> Sunny Days El Palacio | E8: 2026-08-09 | F8: EUR | G8: =IFERROR(INDEX(TB_Master_Bookings!$H$4:$H$1000,MATCH(B8,TB_Master_Bookings!$A$4:$A$1000,0))*INDEX(TB_Master_Bookings!$E$4:$E$1000,MATCH(B8,TB_Master_Bookings!$A$4:$A$1000,0))*INDEX(TB_Hotels_Master!$H$4:$H$1000,MATCH(C8,TB_Hotels_Master!$A$4:$A$1000,0)),0) -> 2520 | H8: =IFERROR(INDEX(TB_Master_Bookings!$L$4:$L$1000,MATCH(B8,TB_Master_Bookings!$A$4:$A$1000,0)),0) -> 49.12 | I8: =G8*H8 -> 123782.4 | J8: Posted
A9: ACC-0001 | B9: MBR-2026-0001 | C9: =IFERROR(INDEX(TB_Master_Bookings!$O$4:$O$1000,MATCH(B9,TB_Master_Bookings!$A$4:$A$1000,0)),"") -> HTL-006 | D9: =IF(C9="","",IFERROR(INDEX(TB_Hotels_Master!$B$4:$B$1000,MATCH(C9,TB_Hotels_Master!$A$4:$A$1000,0)),"HOTEL NOT FOUND")) -> Sun & Sea Beach Resort | E9: 2026-08-22 | F9: EUR | G9: =IFERROR(INDEX(TB_Master_Bookings!$H$4:$H$1000,MATCH(B9,TB_Master_Bookings!$A$4:$A$1000,0))*INDEX(TB_Master_Bookings!$E$4:$E$1000,MATCH(B9,TB_Master_Bookings!$A$4:$A$1000,0))*INDEX(TB_Hotels_Master!$H$4:$H$1000,MATCH(C9,TB_Hotels_Master!$A$4:$A$1000,0)),0) -> 106400 | H9: =IFERROR(INDEX(TB_Master_Bookings!$L$4:$L$1000,MATCH(B9,TB_Master_Bookings!$A$4:$A$1000,0)),0) -> 54.2 | I9: =G9*H9 -> 5766880 | J9: Posted
A10: ACC-0002 | B10: MBR-2026-0002 | C10: =IFERROR(INDEX(TB_Master_Bookings!$O$4:$O$1000,MATCH(B10,TB_Master_Bookings!$A$4:$A$1000,0)),"") -> HTL-007 | D10: =IF(C10="","",IFERROR(INDEX(TB_Hotels_Master!$B$4:$B$1000,MATCH(C10,TB_Hotels_Master!$A$4:$A$1000,0)),"HOTEL NOT FOUND")) -> Coral Hills Resort | E10: 2026-08-22 | F10: USD | G10: =IFERROR(INDEX(TB_Master_Bookings!$H$4:$H$1000,MATCH(B10,TB_Master_Bookings!$A$4:$A$1000,0))*INDEX(TB_Master_Bookings!$E$4:$E$1000,MATCH(B10,TB_Master_Bookings!$A$4:$A$1000,0))*INDEX(TB_Hotels_Master!$H$4:$H$1000,MATCH(C10,TB_Hotels_Master!$A$4:$A$1000,0)),0) -> 19320 | H10: =IFERROR(INDEX(TB_Master_Bookings!$L$4:$L$1000,MATCH(B10,TB_Master_Bookings!$A$4:$A$1000,0)),0) -> 49.3 | I10: =G10*H10 -> 952476 | J10: Posted
A11: ACC-0003 | B11: MBR-2026-0003 | C11: =IFERROR(INDEX(TB_Master_Bookings!$O$4:$O$1000,MATCH(B11,TB_Master_Bookings!$A$4:$A$1000,0)),"") -> HTL-008 | D11: =IF(C11="","",IFERROR(INDEX(TB_Hotels_Master!$B$4:$B$1000,MATCH(C11,TB_Hotels_Master!$A$4:$A$1000,0)),"HOTEL NOT FOUND")) -> Blue Lagoon Palace | E11: 2026-08-24 | F11: GBP | G11: =IFERROR(INDEX(TB_Master_Bookings!$H$4:$H$1000,MATCH(B11,TB_Master_Bookings!$A$4:$A$1000,0))*INDEX(TB_Master_Bookings!$E$4:$E$1000,MATCH(B11,TB_Master_Bookings!$A$4:$A$1000,0))*INDEX(TB_Hotels_Master!$H$4:$H$1000,MATCH(C11,TB_Hotels_Master!$A$4:$A$1000,0)),0) -> 17408 | H11: =IFERROR(INDEX(TB_Master_Bookings!$L$4:$L$1000,MATCH(B11,TB_Master_Bookings!$A$4:$A$1000,0)),0) -> 63.25 | I11: =G11*H11 -> 1101056 | J11: Posted
A12: ACC-0004 | B12: MBR-2026-0004 | C12: =IFERROR(INDEX(TB_Master_Bookings!$O$4:$O$1000,MATCH(B12,TB_Master_Bookings!$A$4:$A$1000,0)),"") -> HTL-009 | D12: =IF(C12="","",IFERROR(INDEX(TB_Hotels_Master!$B$4:$B$1000,MATCH(C12,TB_Hotels_Master!$A$4:$A$1000,0)),"HOTEL NOT FOUND")) -> Desert Rose Plaza | E12: 2026-08-22 | F12: USD | G12: =IFERROR(INDEX(TB_Master_Bookings!$H$4:$H$1000,MATCH(B12,TB_Master_Bookings!$A$4:$A$1000,0))*INDEX(TB_Master_Bookings!$E$4:$E$1000,MATCH(B12,TB_Master_Bookings!$A$4:$A$1000,0))*INDEX(TB_Hotels_Master!$H$4:$H$1000,MATCH(C12,TB_Hotels_Master!$A$4:$A$1000,0)),0) -> 33600 | H12: =IFERROR(INDEX(TB_Master_Bookings!$L$4:$L$1000,MATCH(B12,TB_Master_Bookings!$A$4:$A$1000,0)),0) -> 49.3 | I12: =G12*H12 -> 1656480 | J12: Posted
A13: ACC-0005 | B13: MBR-2026-0005 | C13: =IFERROR(INDEX(TB_Master_Bookings!$O$4:$O$1000,MATCH(B13,TB_Master_Bookings!$A$4:$A$1000,0)),"") -> HTL-010 | D13: =IF(C13="","",IFERROR(INDEX(TB_Hotels_Master!$B$4:$B$1000,MATCH(C13,TB_Hotels_Master!$A$4:$A$1000,0)),"HOTEL NOT FOUND")) -> Seagull Beach Resort | E13: 2026-08-25 | F13: EUR | G13: =IFERROR(INDEX(TB_Master_Bookings!$H$4:$H$1000,MATCH(B13,TB_Master_Bookings!$A$4:$A$1000,0))*INDEX(TB_Master_Bookings!$E$4:$E$1000,MATCH(B13,TB_Master_Bookings!$A$4:$A$1000,0))*INDEX(TB_Hotels_Master!$H$4:$H$1000,MATCH(C13,TB_Hotels_Master!$A$4:$A$1000,0)),0) -> 30940 | H13: =IFERROR(INDEX(TB_Master_Bookings!$L$4:$L$1000,MATCH(B13,TB_Master_Bookings!$A$4:$A$1000,0)),0) -> 54.4 | I13: =G13*H13 -> 1683136 | J13: Posted

Sheet TB_Excursions_Sales
A1: MODULE: EXCURSIONS SALES | T1: 🏠 Back to Home
A2: Daily excursion tickets sold by reps. Auto-calculates commission and EGP equivalent.
A3: Ticket_ID | B3: Sale_Date | C3: Rep_ID | D3: Guest_Name | E3: Hotel | F3: Excursion_Type | G3: Currency | H3: Pax_Qty | I3: Unit_Price_FX | J3: Sale_Amount_FX | K3: CBE_Rate | L3: Sale_Amount_EGP | M3: Payment_Method | N3: Commission_Pct | O3: Rep_Commission_FX | P3: Rep_Commission_EGP | Q3: Deposit_Status | R3: Client_ID (linked)
A4: TCK-1001 | B4: 2026-08-08 | C4: REP-01 | D4: Hans Gruber | E4: Steigenberger Aldau Beach | F4: Luxor Full Day | G4: USD | H4: 1 | I4: 65 | J4: =H4*I4 -> 65 | K4: 49.08 | L4: =J4*K4 -> 3190.2 | M4: Cash | N4: 0.1 | O4: =J4*N4 -> 6.5 | P4: =O4*K4 -> 319.02 | Q4: Deposited | R4: =IFERROR(INDEX(TB_Master_Bookings!$B$4:$B$1000,MATCH(INDEX(TB_Hotels_Master!$A$4:$A$1000,MATCH(E4,TB_Hotels_Master!$B$4:$B$1000,0)),TB_Master_Bookings!$O$4:$O$1000,0)),"") -> CLI-001
A5: TCK-1002 | B5: 2026-08-08 | C5: REP-01 | D5: Ingrid Berg | E5: Steigenberger Aldau Beach | F5: Sea Trip Snorkeling | G5: USD | H5: 1 | I5: 35 | J5: =H5*I5 -> 35 | K5: 49.08 | L5: =J5*K5 -> 1717.8 | M5: POS | N5: 0.12 | O5: =J5*N5 -> 4.2 | P5: =O5*K5 -> 206.136 | Q5: POS Settlement | R5: =IFERROR(INDEX(TB_Master_Bookings!$B$4:$B$1000,MATCH(INDEX(TB_Hotels_Master!$A$4:$A$1000,MATCH(E5,TB_Hotels_Master!$B$4:$B$1000,0)),TB_Master_Bookings!$O$4:$O$1000,0)),"") -> CLI-001
A6: TCK-1003 | B6: 2026-08-08 | C6: REP-02 | D6: Marco Rossi | E6: Jaz Aquamarine Resort | F6: Desert Safari | G6: USD | H6: 1 | I6: 45 | J6: =H6*I6 -> 45 | K6: 49.08 | L6: =J6*K6 -> 2208.6 | M6: Cash | N6: 0.1 | O6: =J6*N6 -> 4.5 | P6: =O6*K6 -> 220.86 | Q6: Deposited | R6: =IFERROR(INDEX(TB_Master_Bookings!$B$4:$B$1000,MATCH(INDEX(TB_Hotels_Master!$A$4:$A$1000,MATCH(E6,TB_Hotels_Master!$B$4:$B$1000,0)),TB_Master_Bookings!$O$4:$O$1000,0)),"") -> CLI-002
A7: TCK-1004 | B7: 2026-08-08 | C7: REP-02 | D7: Lena Weber | E7: Jaz Aquamarine Resort | F7: Luxor Full Day | G7: USD | H7: 1 | I7: 65 | J7: =H7*I7 -> 65 | K7: 49.08 | L7: =J7*K7 -> 3190.2 | M7: POS | N7: 0.1 | O7: =J7*N7 -> 6.5 | P7: =O7*K7 -> 319.02 | Q7: POS Settlement | R7: =IFERROR(INDEX(TB_Master_Bookings!$B$4:$B$1000,MATCH(INDEX(TB_Hotels_Master!$A$4:$A$1000,MATCH(E7,TB_Hotels_Master!$B$4:$B$1000,0)),TB_Master_Bookings!$O$4:$O$1000,0)),"") -> CLI-002
A8: TCK-1005 | B8: 2026-08-08 | C8: REP-03 | D8: James Cole | E8: Sunrise Grand Select | F8: Sea Trip Snorkeling | G8: GBP | H8: 1 | I8: 35 | J8: =H8*I8 -> 35 | K8: 62.15 | L8: =J8*K8 -> 2175.25 | M8: Cash | N8: 0.12 | O8: =J8*N8 -> 4.2 | P8: =O8*K8 -> 261.03 | Q8: Deposited | R8: =IFERROR(INDEX(TB_Master_Bookings!$B$4:$B$1000,MATCH(INDEX(TB_Hotels_Master!$A$4:$A$1000,MATCH(E8,TB_Hotels_Master!$B$4:$B$1000,0)),TB_Master_Bookings!$O$4:$O$1000,0)),"") -> CLI-003
A9: TCK-1006 | B9: 2026-08-08 | C9: REP-01 | D9: Otto Frank | E9: Steigenberger Aldau Beach | F9: Quad Bike Safari | G9: USD | H9: 1 | I9: 45 | J9: =H9*I9 -> 45 | K9: 49.08 | L9: =J9*K9 -> 2208.6 | M9: Cash | N9: 0.1 | O9: =J9*N9 -> 4.5 | P9: =O9*K9 -> 220.86 | Q9: Deposited | R9: =IFERROR(INDEX(TB_Master_Bookings!$B$4:$B$1000,MATCH(INDEX(TB_Hotels_Master!$A$4:$A$1000,MATCH(E9,TB_Hotels_Master!$B$4:$B$1000,0)),TB_Master_Bookings!$O$4:$O$1000,0)),"") -> CLI-001
A10: TCK-1007 | B10: 2026-08-08 | C10: REP-04 | D10: Sara Nilsson | E10: Pickalbatros Aqua Blu | F10: Desert Safari | G10: EUR | H10: 1 | I10: 45 | J10: =H10*I10 -> 45 | K10: 53.35 | L10: =J10*K10 -> 2400.75 | M10: POS | N10: 0.1 | O10: =J10*N10 -> 4.5 | P10: =O10*K10 -> 240.075 | Q10: POS Settlement | R10: =IFERROR(INDEX(TB_Master_Bookings!$B$4:$B$1000,MATCH(INDEX(TB_Hotels_Master!$A$4:$A$1000,MATCH(E10,TB_Hotels_Master!$B$4:$B$1000,0)),TB_Master_Bookings!$O$4:$O$1000,0)),"") -> CLI-004
A11: TCK-1008 | B11: 2026-08-08 | C11: REP-02 | D11: Tom Baker | E11: Jaz Aquamarine Resort | F11: Sea Trip Snorkeling | G11: USD | H11: 1 | I11: 35 | J11: =H11*I11 -> 35 | K11: 49.08 | L11: =J11*K11 -> 1717.8 | M11: Cash | N11: 0.12 | O11: =J11*N11 -> 4.2 | P11: =O11*K11 -> 206.136 | Q11: Deposited | R11: =IFERROR(INDEX(TB_Master_Bookings!$B$4:$B$1000,MATCH(INDEX(TB_Hotels_Master!$A$4:$A$1000,MATCH(E11,TB_Hotels_Master!$B$4:$B$1000,0)),TB_Master_Bookings!$O$4:$O$1000,0)),"") -> CLI-002
A12: TCK-1009 | B12: 2026-08-08 | C12: REP-03 | D12: Alice Wu | E12: Sunrise Grand Select | F12: Luxor Full Day | G12: GBP | H12: 1 | I12: 65 | J12: =H12*I12 -> 65 | K12: 62.15 | L12: =J12*K12 -> 4039.75 | M12: POS | N12: 0.1 | O12: =J12*N12 -> 6.5 | P12: =O12*K12 -> 403.975 | Q12: POS Settlement | R12: =IFERROR(INDEX(TB_Master_Bookings!$B$4:$B$1000,MATCH(INDEX(TB_Hotels_Master!$A$4:$A$1000,MATCH(E12,TB_Hotels_Master!$B$4:$B$1000,0)),TB_Master_Bookings!$O$4:$O$1000,0)),"") -> CLI-003
A13: TCK-1010 | B13: 2026-08-08 | C13: REP-04 | D13: Karl Braun | E13: Pickalbatros Aqua Blu | F13: Quad Bike Safari | G13: EUR | H13: 1 | I13: 45 | J13: =H13*I13 -> 45 | K13: 53.35 | L13: =J13*K13 -> 2400.75 | M13: Cash | N13: 0.1 | O13: =J13*N13 -> 4.5 | P13: =O13*K13 -> 240.075 | Q13: Deposited | R13: =IFERROR(INDEX(TB_Master_Bookings!$B$4:$B$1000,MATCH(INDEX(TB_Hotels_Master!$A$4:$A$1000,MATCH(E13,TB_Hotels_Master!$B$4:$B$1000,0)),TB_Master_Bookings!$O$4:$O$1000,0)),"") -> CLI-004
A14: TKT-1001 | B14: 2026-08-16 | C14: REP-HRG-01 | D14: Anna Schmidt | E14: Sun & Sea Beach Resort | F14: Sea Trip | G14: EUR | H14: 1 | I14: 35 | J14: =H14*I14 -> 35 | K14: 53.85 | L14: =J14*K14 -> 1884.75 | M14: Cash | N14: 0.12 | O14: =J14*N14 -> 4.2 | P14: =O14*K14 -> 226.17 | Q14: Deposited | R14: =IFERROR(INDEX(TB_Master_Bookings!$B$4:$B$1000,MATCH(INDEX(TB_Hotels_Master!$A$4:$A$1000,MATCH(E14,TB_Hotels_Master!$B$4:$B$1000,0)),TB_Master_Bookings!$O$4:$O$1000,0)),"") -> CLI-006
A15: TKT-1002 | B15: 2026-08-16 | C15: REP-HRG-01 | D15: Mark Weber | E15: Sun & Sea Beach Resort | F15: Sea Trip | G15: EUR | H15: 1 | I15: 35 | J15: =H15*I15 -> 35 | K15: 53.85 | L15: =J15*K15 -> 1884.75 | M15: POS | N15: 0.12 | O15: =J15*N15 -> 4.2 | P15: =O15*K15 -> 226.17 | Q15: POS Settlement | R15: =IFERROR(INDEX(TB_Master_Bookings!$B$4:$B$1000,MATCH(INDEX(TB_Hotels_Master!$A$4:$A$1000,MATCH(E15,TB_Hotels_Master!$B$4:$B$1000,0)),TB_Master_Bookings!$O$4:$O$1000,0)),"") -> CLI-006
... A20: TKT-1007 | B20: 2026-08-16 | C20: REP-HRG-01 | D20: Laura Becker | E20: Sun & Sea Beach Resort | F20: Luxor | G20: EUR | H20: 1 | I20: 65 | J20: =H20*I20 -> 65 | K20: 53.85 | L20: =J20*K20 -> 3500.25 | M20: Cash | N20: 0.1 | O20: =J20*N20 -> 6.5 | P20: =O20*K20 -> 350.025 | Q20: Deposited | R20: =IFERROR(INDEX(TB_Master_Bookings!$B$4:$B$1000,MATCH(INDEX(TB_Hotels_Master!$A$4:$A$1000,MATCH(E20,TB_Hotels_Master!$B$4:$B$1000,0)),TB_Master_Bookings!$O$4:$O$1000,0)),"") -> CLI-006
A21: TKT-1008 | B21: 2026-08-16 | C21: REP-HRG-01 | D21: Paul Wagner | E21: Sun & Sea Beach Resort | F21: Sea Trip | G21: EUR | H21: 1 | I21: 35 | J21: =H21*I21 -> 35 | K21: 53.85 | L21: 1884.75 | M21: POS | N21: 0.12 | O21: =J21*N21 -> 4.2 | P21: =O21*K21 -> 226.17 | Q21: POS Settlement | R21: =IFERROR(INDEX(TB_Master_Bookings!$B$4:$B$1000,MATCH(INDEX(TB_Hotels_Master!$A$4:$A$1000,MATCH(E21,TB_Hotels_Master!$B$4:$B$1000,0)),TB_Master_Bookings!$O$4:$O$1000,0)),"") -> CLI-006

Sheet TB_Cash_Rep_Reconciliation
A1: MODULE: CASH RECONCILIATION | L1: 🏠 Back to Home
A2: Daily cash reconciliation per rep. Expected = Cash + POS - Commission. Variance = Actual - Expected.
A3: Reconciliation_ID | B3: Rep_ID | C3: Business_Date | D3: Total_Cash_Collected_EGP | E3: POS_Amount_EGP | F3: Commission_Deducted_EGP | G3: Expected_Net_Cash_EGP | H3: Actual_Net_Cash_Deposited_EGP | I3: Variance_EGP | J3: Status
A4: REC-0001 | B4: REP-01 | C4: 2026-08-08 | D4: 7607.4 | E4: 2208.6 | F4: 1074.85 | G4: =D4+E4-F4 -> 8741.15 | H4: 8920 | I4: =H4-G4 -> 178.85 | J4: Exception
A5: REC-0002 | B5: REP-02 | C5: 2026-08-08 | D5: 4908 | E5: 4662.6 | F5: 1050.31 | G5: =D5+E5-F5 -> 8520.29 | H5: 8520.29 | I5: =H5-G5 -> 0 | J5: Reconciled
A6: REC-0003 | B6: REP-03 | C6: 2026-08-08 | D6: 2486 | E6: 4972 | F6: 845.24 | G6: =D6+E6-F6 -> 6612.76 | H6: 6612.76 | I6: =H6-G6 -> 0 | J6: Reconciled
A7: REC-0004 | B7: REP-04 | C7: 2026-08-08 | D7: 2934.25 | E7: 2667.5 | F7: 560.18 | G7: =D7+E7-F7 -> 5041.57 | H7: 5041.57 | I7: =H7-G7 -> 0 | J7: Reconciled
A8: REC-0005 | B8: REP-HRG-01 | C8: 2026-08-16 | D8: 7808.25 | E8: 3769.5 | F8: 1200.86 | G8: =D8+E8-F8 -> 10376.89 | H8: 10600 | I8: =H8-G8 -> 223.11 | J8: Exception
A9: REC-0006 | B9: REP-HRG-02 | C9: 2026-08-17 | D9: 4312 | E9: 3503.5 | F9: 749.21 | G9: =D9+E9-F9 -> 7066.29 | H9: 7066.29 | I9: =H9-G9 -> 0 | J9: Reconciled
A10: REC-0007 | B10: REP-HRG-03 | C10: 2026-08-18 | D10: 2500 | E10: 1200 | F10: 300 | G10: =D10+E10-F10 -> 3400 | H10: 3400 | I10: =H10-G10 -> 0 | J10: Reconciled

Sheet TB_AP_Invoices
A1: MODULE: ACCOUNTS PAYABLE - INVOICES | P1: 🏠 Back to Home
A2: Supplier invoices for hotels, transport, and excursions. Linked to bookings and accruals.
A3: Invoice_ID | B3: Supplier_ID | C3: Supplier_Name | D3: Invoice_Type | E3: Invoice_Date | F3: Due_Date | G3: Booking_Ref | H3: Currency | I3: Amount_FX | J3: CBE_Rate | K3: Amount_EGP | L3: VAT_Amount_EGP | M3: Total_EGP | N3: Status
A4: AP-0001 | B4: =IFERROR(INDEX(TB_Hotels_Master!$O$4:$O$1000,MATCH(INDEX(TB_Hotel_Accruals!$C$4:$C$1000,MATCH(G4,TB_Hotel_Accruals!$B$4:$B$1000,0)),TB_Hotels_Master!$A$4:$A$1000,0)),"") -> SUP-HTL-001 | C4: =IF(B4="","",IFERROR(INDEX(TB_Suppliers_Master!$B$4:$B$1000,MATCH(B4,TB_Suppliers_Master!$A$4:$A$1000,0)),"INVALID SUPPLIER ID")) -> Steigenberger Aldau Beach | D4: Hotel | E4: 2026-08-09 | F4: 2026-09-08 | G4: HRG-2026-0815 | H4: EUR | I4: =IFERROR(INDEX(TB_Hotel_Accruals!$G$4:$G$1000,MATCH(G4,TB_Hotel_Accruals!$B$4:$B$1000,0)),0) -> 100800 | J4: 53.35 | K4: =M4/1.14 -> 4717263.2 | L4: =M4-K4 -> 660416.84 | M4: =I4*J4 -> 5377680 | N4: Pending
A5: AP-0002 | B5: =IFERROR(INDEX(TB_Hotels_Master!$O$4:$O$1000,MATCH(INDEX(TB_Hotel_Accruals!$C$4:$C$1000,MATCH(G5,TB_Hotel_Accruals!$B$4:$B$1000,0)),TB_Hotels_Master!$A$4:$A$1000,0)),"") -> SUP-HTL-002 | C5: =IF(B5="","",IFERROR(INDEX(TB_Suppliers_Master!$B$4:$B$1000,MATCH(B5,TB_Suppliers_Master!$A$4:$A$1000,0)),"INVALID SUPPLIER ID")) -> Jaz Aquamarine Resort | D5: Hotel | E5: 2026-08-10 | F5: 2026-09-09 | G5: HRG-2026-0816 | H5: USD | I5: =IFERROR(INDEX(TB_Hotel_Accruals!$G$4:$G$1000,MATCH(G5,TB_Hotel_Accruals!$B$4:$B$1000,0)),0) -> 20475 | J5: 49.12 | K5: =M5/1.14 -> 882221.05 | L5: =M5-K5 -> 123510.95 | M5: =I5*J5 -> 1005732 | N5: Pending
A6: AP-0003 | B6: =IFERROR(INDEX(TB_Hotels_Master!$O$4:$O$1000,MATCH(INDEX(TB_Hotel_Accruals!$C$4:$C$1000,MATCH(G6,TB_Hotel_Accruals!$B$4:$B$1000,0)),TB_Hotels_Master!$A$4:$A$1000,0)),"") -> SUP-HTL-003 | C6: =IF(B6="","",IFERROR(INDEX(TB_Suppliers_Master!$B$4:$B$1000,MATCH(B6,TB_Suppliers_Master!$A$4:$A$1000,0)),"INVALID SUPPLIER ID")) -> Sunrise Grand Select | D6: Hotel | E6: 2026-08-11 | F6: 2026-09-25 | G6: HRG-2026-0817 | H6: GBP | I6: =IFERROR(INDEX(TB_Hotel_Accruals!$G$4:$G$1000,MATCH(G6,TB_Hotel_Accruals!$B$4:$B$1000,0)),0) -> 13020 | J6: 62.3 | K6: =M6/1.14 -> 711531.58 | L6: =M6-K6 -> 99614.421 | M6: =I6*J6 -> 811146 | N6: Pending
A7: AP-0004 | B7: =IFERROR(INDEX(TB_Hotels_Master!$O$4:$O$1000,MATCH(INDEX(TB_Hotel_Accruals!$C$4:$C$1000,MATCH(G7,TB_Hotel_Accruals!$B$4:$B$1000,0)),TB_Hotels_Master!$A$4:$A$1000,0)),"") -> SUP-HTL-004 | C7: =IF(B7="","",IFERROR(INDEX(TB_Suppliers_Master!$B$4:$B$1000,MATCH(B7,TB_Suppliers_Master!$A$4:$A$1000,0)),"INVALID SUPPLIER ID")) -> Sun & Sea Beach Resort | D7: Hotel | E7: 2026-08-23 | F7: 2026-09-22 | G7: MBR-2026-0001 | H7: EUR | I7: =IFERROR(INDEX(TB_Hotel_Accruals!$G$4:$G$1000,MATCH(G7,TB_Hotel_Accruals!$B$4:$B$1000,0)),0) -> 106400 | J7: 54.2 | K7: =M7/1.14 -> 5058666.7 | L7: =M7-K7 -> 708213.33 | M7: =I7*J7 -> 5766880 | N7: Pending
A8: AP-0005 | B8: =IFERROR(INDEX(TB_Hotels_Master!$O$4:$O$1000,MATCH(INDEX(TB_Hotel_Accruals!$C$4:$C$1000,MATCH(G8,TB_Hotel_Accruals!$B$4:$B$1000,0)),TB_Hotels_Master!$A$4:$A$1000,0)),"") -> SUP-HTL-005 | C8: =IF(B8="","",IFERROR(INDEX(TB_Suppliers_Master!$B$4:$B$1000,MATCH(B8,TB_Suppliers_Master!$A$4:$A$1000,0)),"INVALID SUPPLIER ID")) -> Coral Hills Resort | D8: Hotel | E8: 2026-08-23 | F8: 2026-09-22 | G8: MBR-2026-0002 | H8: USD | I8: =IFERROR(INDEX(TB_Hotel_Accruals!$G$4:$G$1000,MATCH(G8,TB_Hotel_Accruals!$B$4:$B$1000,0)),0) -> 19320 | J8: 49.3 | K8: =M8/1.14 -> 835505.26 | L8: =M8-K8 -> 116970.74 | M8: =I8*J8 -> 952476 | N8: Pending
A9: AP-0006 | B9: =IFERROR(INDEX(TB_Hotels_Master!$O$4:$O$1000,MATCH(INDEX(TB_Hotel_Accruals!$C$4:$C$1000,MATCH(G9,TB_Hotel_Accruals!$B$4:$B$1000,0)),TB_Hotels_Master!$A$4:$A$1000,0)),"") -> SUP-HTL-006 | C9: =IF(B9="","",IFERROR(INDEX(TB_Suppliers_Master!$B$4:$B$1000,MATCH(B9,TB_Suppliers_Master!$A$4:$A$1000,0)),"INVALID SUPPLIER ID")) -> Blue Lagoon Palace | D9: Hotel | E9: 2026-08-25 | F9: 2026-10-09 | G9: MBR-2026-0003 | H9: GBP | I9: =IFERROR(INDEX(TB_Hotel_Accruals!$G$4:$G$1000,MATCH(G9,TB_Hotel_Accruals!$B$4:$B$1000,0)),0) -> 17408 | J9: 63.25 | K9: =M9/1.14 -> 965838.6 | L9: =M9-K9 -> 135217.4 | M9: =I9*J9 -> 1101056 | N9: Pending
A10: AP-0007 | B10: =IFERROR(INDEX(TB_Hotels_Master!$O$4:$O$1000,MATCH(INDEX(TB_Hotel_Accruals!$C$4:$C$1000,MATCH(G10,TB_Hotel_Accruals!$B$4:$B$1000,0)),TB_Hotels_Master!$A$4:$A$1000,0)),"") -> SUP-HTL-007 | C10: =IF(B10="","",IFERROR(INDEX(TB_Suppliers_Master!$B$4:$B$1000,MATCH(B10,TB_Suppliers_Master!$A$4:$A$1000,0)),"INVALID SUPPLIER ID")) -> Desert Rose Plaza | D10: Hotel | E10: 2026-08-23 | F10: 2026-09-22 | G10: MBR-2026-0004 | H10: USD | I10: =IFERROR(INDEX(TB_Hotel_Accruals!$G$4:$G$1000,MATCH(G10,TB_Hotel_Accruals!$B$4:$B$1000,0)),0) -> 33600 | J10: 49.3 | K10: =M10/1.14 -> 1453052.6 | L10: =M10-K10 -> 203427.37 | M10: =I10*J10 -> 1656480 | N10: Pending
A11: AP-0008 | B11: =IFERROR(INDEX(TB_Hotels_Master!$O$4:$O$1000,MATCH(INDEX(TB_Hotel_Accruals!$C$4:$C$1000,MATCH(G11,TB_Hotel_Accruals!$B$4:$B$1000,0)),TB_Hotels_Master!$A$4:$A$1000,0)),"") -> SUP-HTL-008 | C11: =IF(B11="","",IFERROR(INDEX(TB_Suppliers_Master!$B$4:$B$1000,MATCH(B11,TB_Suppliers_Master!$A$4:$A$1000,0)),"INVALID SUPPLIER ID")) -> Seagull Beach Resort | D11: Hotel | E11: 2026-08-26 | F11: 2026-09-25 | G11: MBR-2026-0005 | H11: EUR | I11: =IFERROR(INDEX(TB_Hotel_Accruals!$G$4:$G$1000,MATCH(G11,TB_Hotel_Accruals!$B$4:$B$1000,0)),0) -> 30940 | J11: 54.4 | K11: =M11/1.14 -> 1476435.1 | L11: =M11-K11 -> 206700.91 | M11: =I11*J11 -> 1683136 | N11: Pending

Sheet TB_Bank_Reconciliation
A1: MODULE: BANK RECONCILIATION | Q1: 🏠 Back to Home
A2: Match bank statements with journal entries. Auto-flags unmatched items and calculates reconciled balance.
A3: Recon_ID | B3: Bank_Account | C3: Statement_Date | D3: Statement_Balance_FX | E3: FX_Currency | F3: CBE_Rate | G3: Statement_Balance_EGP | H3: GL_Balance_EGP | I3: Difference_EGP | J3: Unmatched_Dr_Count | K3: Unmatched_Cr_Count | L3: Status | M3: Reconciled_By | N3: Recon_Date | O3: Notes
A4: BR-0001 | B4: Bank - FCY Operations (1001) | C4: 2026-08-31 | D4: 26384.21 | E4: USD | F4: 49.4 | G4: 1303380 | H4: 1302560 | I4: 820 | J4: 2 | K4: 1 | L4: Exception | M4: Ahmed Hassan | N4: 2026-09-01 | O4: 2 unmatched deposits, 1 unmatched withdrawal
A5: BR-0002 | B5: Bank Account - EUR (1011) | C5: 2026-08-31 | D5: 124532.71 | E5: EUR | F5: 53.4 | G5: 6650046.7 | H5: 6650000 | I5: 0 | J5: 0 | K5: 0 | L5: Reconciled | M5: Sara Khaled | N5: 2026-09-01 | O5: Perfect match - all items cleared
A6: BR-0003 | B6: Bank - FCY Operations (1001) | C6: 2026-08-25 | D6: 26384.21 | E6: USD | F6: 49.4 | G6: 1303380 | H6: 1302560 | I6: 820 | J6: 2 | K6: 1 | L6: Exception | M6: Ahmed Hassan | N6: 2026-08-26 | O6: Pending bank charges clarification
A7: BR-0004 | B7: Bank Account - EUR (1011) | C7: 2026-08-25 | D7: 124532.71 | E7: EUR | F7: 53.4 | G7: 6650046.7 | H7: 6650000 | I7: 0 | J7: 0 | K7: 0 | L7: Reconciled | M7: Sara Khaled | N7: 2026-08-26 | O7: Weekly reconciliation completed
A8: BR-0005 | B8: Bank - FCY Operations (1001) | C8: 2026-08-15 | D8: 15000 | E8: USD | F8: 49.15 | G8: 737250 | H8: 737250 | I8: 0 | J8: 0 | K8: 0 | L8: Reconciled | M8: Ahmed Hassan | N8: 2026-08-16 | O8: Mid-month check

Sheet TB_Budget_vs_Actual
A1: MODULE: BUDGET VS ACTUAL | O1: 🏠 Back to Home
A2: Monthly budget tracking and variance analysis. Auto-calculates variance % and flags significant deviations (>10%).
A3: Period | B3: Account_Code | C3: Account_Name | D3: Account_Type | E3: Budget_EGP | F3: Actual_EGP | G3: Variance_EGP | H3: Variance_Pct | I3: Status | J3: YTD_Budget_EGP | K3: YTD_Actual_EGP | L3: YTD_Variance_Pct | M3: Notes
A4: 2026-08 | B4: 4000 | C4: Revenue - Package Tours (Bookings) | D4: Revenue | E4: 8000000 | F4: 6615400 | G4: =F4-E4 -> -1384600 | H4: =IF(E4=0,"N/A",G4/E4) -> -0.173075 | I4: =IF(G4>0,"Over Budget",IF(G4<0,"Under Budget","On Target")) -> Under Budget | J4: 8000000 | K4: 6615400 | L4: =IF(J4=0,"N/A",(K4-J4)/J4) -> -0.173075 | M4: August peak season - slightly below target
A5: 2026-08 | B5: 4100 | C5: Revenue - In-Resort Excursions | D5: Revenue | E5: 8000 | F5: 4662.6 | G5: =F5-E5 -> -3337.4 | H5: =IF(E5=0,"N/A",G5/E5) -> -0.417175 | I5: =IF(G5>0,"Over Budget",IF(G5<0,"Under Budget","On Target")) -> Under Budget | J5: 8000 | K5: 4662.6 | L5: =IF(J5=0,"N/A",(K5-J5)/J5) -> -0.417175 | M5: Low excursion sales - weather impact
A6: 2026-08 | B6: 4101 | C6: Revenue - Inbound Packages | D6: Revenue | E6: 3500000 | F6: 2995263.2 | G6: =F6-E6 -> -504736.84 | H6: =IF(E6=0,"N/A",G6/E6) -> -0.14421053 | I6: =IF(G6>0,"Over Budget",IF(G6<0,"Under Budget","On Target")) -> Under Budget | J6: 3500000 | K6: 2995263.2 | L6: =IF(J6=0,"N/A",(K6-J6)/J6) -> -0.14421053 | M6: New clients ramping up
A7: 2026-08 | B7: 4900 | C7: Realized FX Gain | D7: Revenue | E7: 50000 | F7: 34600 | G7: =F7-E7 -> -15400 | H7: =IF(E7=0,"N/A",G7/E7) -> -0.308 | I7: =IF(G7>0,"Over Budget",IF(G7<0,"Under Budget","On Target")) -> Under Budget | J7: 50000 | K7: 34600 | L7: =IF(J7=0,"N/A",(K7-J7)/J7) -> -0.308 | M7: FX volatility lower than forecast
A8: 2026-08 | B8: 5000 | C8: Cost of Sales - Hotel Accommodation | D8: Expense | E8: 25000 | F8: 20273 | G8: =F8-E8 -> -4727 | H8: =IF(E8=0,"N/A",G8/E8) -> -0.18908 | I8: =IF(G8>0,"Over Budget",IF(G8<0,"Under Budget","On Target")) -> Under Budget | J8: 25000 | K8: 20273 | L8: =IF(J8=0,"N/A",(K8-J8)/J8) -> -0.18908 | M8: Within acceptable range
A9: 2026-08 | B9: 5101 | C9: COGS - Hotel Contracts | D9: Expense | E9: 2500000 | F9: 2124640 | G9: =F9-E9 -> -375360 | H9: =IF(E9=0,"N/A",G9/E9) -> -0.150144 | I9: =IF(G9>0,"Over Budget",IF(G9<0,"Under Budget","On Target")) -> Under Budget | J9: 2500000 | K9: 2124640 | L9: =IF(J9=0,"N/A",(K9-J9)/J9) -> -0.150144 | M9: Contract renegotiation pending
A10: 2026-08 | B10: 5300 | C10: Rep Commission Expense | D10: Expense | E10: 800 | F10: 559.51 | G10: =F10-E10 -> -240.49 | H10: =IF(E10=0,"N/A",G10/E10) -> -0.3006125 | I10: =IF(G10>0,"Over Budget",IF(G10<0,"Under Budget","On Target")) -> Under Budget | J10: 800 | K10: 559.51 | L10: =IF(J10=0,"N/A",(K10-J10)/J10) -> -0.3006125 | M10: Commission rate higher than planned
A11: 2026-08 | B11: 5401 | C11: FX Gain/Loss | D11: Expense/Income | E11: 0 | F11: -12600 | G11: =F11-E11 -> -12600 | H11: =IF(E11=0,"N/A",G11/E11) -> N/A | I11: =IF(G11>0,"Over Budget",IF(G11<0,"Under Budget","On Target")) -> Under Budget | J11: 0 | K11: -12600 | L11: =IF(J11=0,"N/A",(K11-J11)/J11) -> N/A | M11: Gain booked - favorable movement
A12: 2026-08 | B12: 2101 | C12: Output VAT Payable (14%) | D12: Liability | E12: 420000 | F12: 419336.84 | G12: =F12-E12 -> -663.16 | H12: =IF(E12=0,"N/A",G12/E12) -> -0.0015789524 | I12: =IF(G12>0,"Over Budget",IF(G12<0,"Under Budget","On Target")) -> Under Budget | J12: 420000 | K12: 419336.84 | L12: =IF(J12=0,"N/A",(K12-J12)/J12) -> -0.0015789524 | M12: VAT tracking accurate
A13: 2026-08 | B13: 2300 | C13: Rep Commission Payable | D13: Liability | E13: 600 | F13: 559.51 | G13: =F13-E13 -> -40.49 | H13: =IF(E13=0,"N/A",G13/E13) -> -0.067483333 | I13: =IF(G13>0,"Over Budget",IF(G13<0,"Under Budget","On Target")) -> Under Budget | J13: 600 | K13: 559.51 | L13: =IF(J13=0,"N/A",(K13-J13)/J13) -> -0.067483333 | M13: Accrued commissions aligned
